#VRML_SIM R2022a utf8
WorldInfo {
  basicTimeStep 5
}
Viewpoint {
  orientation 0.00937446525865025 0.009207652146147565 -0.999913665544716 1.5888363242007733
  position 0.058494565332308665 8.468991548522489 1.9156112378753718
}
TexturedBackground {
}
TexturedBackgroundLight {
}
RectangleArena {
  floorSize 5 5
  floorTileSize 0.25 0.25
  wallHeight 0.05
}
Robot {
  translation 0 0 0.05
  children [
    DEF Base Solid {
      translation 0 0 0.05
      children [
        Shape {
          appearance Asphalt {
          }
          geometry Box {
            size 2 2 0.1
          }
        }
        HingeJoint {
          jointParameters HingeJointParameters {
            position 1.49
            axis 0 1 0
          }
          endPoint Solid {
            translation -0.04991670832341408 0 0.4975020826390133
            rotation 0 -1 0 0.09999999999999855
            children [
              InertialUnit {
                rotation 0 0 1 1.5707996938995747
                name "imu"
              }
              HingeJoint {
                jointParameters HingeJointParameters {
                  axis 0 1 0
                  anchor 0 0 0.18
                }
                device [
                  RotationalMotor {
                    name "balance_motor"
                    controlPID 0.0001 0 0
                    maxTorque 100
                  }
                  PositionSensor {
                    name "pendulum_position"
                  }
                ]
                endPoint Solid {
                  translation 0 0 3
                  rotation 0 1 0 0
                  children [
                    Shape {
                      appearance GlossyPaint {
                        baseColor 0.4 1 1
                      }
                      geometry Sphere {
                        radius 0.1
                      }
                    }
                  ]
                  name "rider"
                  boundingObject Sphere {
                    radius 0.1
                  }
                  physics Physics {
                    mass 2
                  }
                }
              }
              Shape {
                appearance GalvanizedMetal {
                }
                geometry Sphere {
                  radius 0.1
                }
              }
            ]
            name "frame"
            boundingObject Sphere {
              radius 0.1
            }
            physics Physics {
              mass 39.2
            }
          }
        }
      ]
      name "base"
      boundingObject Shape {
        geometry Box {
          size 2 2 0.1
        }
      }
      physics Physics {
        mass 10
      }
    }
  ]
  boundingObject Box {
    size 2 2 0.01
  }
  physics Physics {
  }
  controller "Pendulum_Controller"
}
