#VRML_SIM R2022a utf8
WorldInfo {
  basicTimeStep 5
}
Viewpoint {
  orientation 0.018121165184248368 0.017709919622346852 -0.9996789395197516 1.5940710262540514
  position 0.24747046899695352 6.31525042896743 1.1842810949980613
}
TexturedBackground {
}
TexturedBackgroundLight {
}
RectangleArena {
  floorSize 5 5
  floorTileSize 0.25 0.25
  wallHeight 0.05
}
Robot {
  translation 0 0 0.05
  children [
    DEF Base Solid {
      translation 0 0 0.05
      children [
        Shape {
          appearance Asphalt {
          }
          geometry Box {
            size 2 2 0.1
          }
        }
        HingeJoint {
          jointParameters HingeJointParameters {
            position 1.594
            axis 0 1 0
          }
          endPoint DEF Frame Solid {
            translation -6.155451778765315e-05 4.599743406634782e-10 0.5500682375851593
            rotation -2.936807961373253e-06 -0.9999999999930208 -2.309463200050964e-06 8.963317864079629e-06
            children [
              InertialUnit {
                translation 0 0 0.5
                rotation 0 0 1 1.5708
                name "imu"
              }
              Solid {
                translation 0 0 0.5
                children [
                  Shape {
                    appearance PBRAppearance {
                    }
                    geometry Sphere {
                      radius 0.1
                    }
                  }
                ]
                name "frame mass"
                physics Physics {
                  mass 1
                }
              }
              HingeJoint {
                jointParameters HingeJointParameters {
                  axis 0 1 0
                  anchor 0 0 0.5
                }
                device [
                  RotationalMotor {
                    name "balance_motor"
                    controlPID 0.0001 0 0
                    maxTorque 1000000
                  }
                  PositionSensor {
                    name "pendulum_position"
                  }
                ]
                endPoint DEF Rider Solid {
                  translation -3.952892435815994e-06 -1.374842207531869e-14 1.0000058118750061
                  rotation 1.0732781572061393e-09 -1 -9.92571827280791e-11 9.062111501412559e-06
                  children [
                    Group {
                      children [
                        DEF RiderMass Solid {
                          translation 0 0 0.6
                          children [
                            Shape {
                              appearance Plastic {
                              }
                              geometry Sphere {
                                radius 0.1
                              }
                            }
                          ]
                          name "riderMass"
                          boundingObject Sphere {
                            radius 0.1
                          }
                          physics Physics {
                          }
                        }
                      ]
                    }
                    Shape {
                      appearance Plastic {
                      }
                      geometry Box {
                        size 0.1 0.1 1
                      }
                    }
                  ]
                  name "rider"
                  boundingObject Shape {
                    geometry Box {
                      size 0.1 0.1 1
                    }
                  }
                  physics Physics {
                    mass 1e-05
                  }
                }
              }
              Shape {
                appearance OldSteel {
                }
                geometry Box {
                  size 0.1 0.1 1
                }
              }
            ]
            name "frame"
            boundingObject Shape {
              geometry Box {
                size 0.1 0.1 1
              }
            }
            physics Physics {
              mass 1e-05
            }
          }
        }
      ]
      name "base"
      boundingObject Shape {
        geometry Box {
          size 2 2 0.1
        }
      }
      physics Physics {
      }
    }
  ]
  boundingObject Box {
    size 2 2 0.01
  }
  physics Physics {
  }
  controller "Pendulum_Controller"
}
