#VRML_SIM R2022a utf8
WorldInfo {
  basicTimeStep 16
}
Viewpoint {
  orientation 0.06986571205716027 -0.04695156829793327 -0.9964508680878904 4.321710234239086
  position 3.494642998930647 -8.893266861502457 1.608679624866569
}
TexturedBackground {
}
TexturedBackgroundLight {
}
RectangleArena {
  floorSize 5 5
  floorTileSize 0.25 0.25
  wallHeight 0.05
}
Robot {
  translation 0 0 0.05
  children [
    DEF Base Solid {
      translation 0 0 0.05
      children [
        Shape {
          appearance Asphalt {
          }
          geometry Box {
            size 2 2 0.1
          }
        }
        HingeJoint {
          jointParameters HingeJointParameters {
            position 1.594
            axis 0 1 0
          }
          endPoint DEF Frame Solid {
            translation 0.00033494924449168663 4.600634519220598e-10 0.5499990309402717
            rotation -1.3792528386839552e-07 0.9999999999999845 -1.0867307550875921e-07 0.0001916089509871777
            children [
              InertialUnit {
                name "imu"
              }
              Solid {
                children [
                  Shape {
                    appearance PBRAppearance {
                    }
                    geometry Sphere {
                      radius 0.1
                    }
                  }
                ]
                name "frame mass"
                physics Physics {
                  mass 1
                }
              }
              HingeJoint {
                jointParameters HingeJointParameters {
                  axis 0 1 0
                  anchor 0 0 0.5
                }
                device [
                  PositionSensor {
                  }
                  RotationalMotor {
                  }
                ]
                endPoint DEF Rider Solid {
                  translation -1.3877787807814457e-17 0 0.9999999999999999
                  rotation 0 1 0 0
                  children [
                    Group {
                      children [
                        DEF RiderMass Solid {
                          translation 0 0 0.6
                          children [
                            Shape {
                              appearance Plastic {
                              }
                              geometry Sphere {
                                radius 0.1
                              }
                            }
                          ]
                          name "riderMass"
                          boundingObject Sphere {
                            radius 0.1
                          }
                          physics Physics {
                          }
                        }
                      ]
                    }
                    Shape {
                      appearance Plastic {
                      }
                      geometry Box {
                        size 0.1 0.1 1
                      }
                    }
                  ]
                  name "rider"
                  boundingObject Shape {
                    geometry Box {
                      size 0.1 0.1 1
                    }
                  }
                  physics Physics {
                  }
                }
              }
              Shape {
                appearance OldSteel {
                }
                geometry Box {
                  size 0.1 0.1 1
                }
              }
            ]
            name "frame"
            boundingObject Shape {
              geometry Box {
                size 0.1 0.1 1
              }
            }
            physics Physics {
            }
          }
        }
      ]
      name "base"
      boundingObject Shape {
        geometry Box {
          size 2 2 0.1
        }
      }
      physics Physics {
      }
      locked TRUE
    }
  ]
  boundingObject Box {
    size 2 2 0.01
  }
  physics Physics {
  }
}
