#VRML_SIM R2022a utf8
WorldInfo {
  basicTimeStep 16
}
Viewpoint {
  orientation 0.06986571205716027 -0.04695156829793327 -0.9964508680878904 4.321710234239086
  position 1.5238651257739106 -4.062999816821553 0.8735123009014331
}
TexturedBackground {
}
TexturedBackgroundLight {
}
RectangleArena {
  floorSize 5 5
  floorTileSize 0.25 0.25
  wallHeight 0.05
}
Robot {
  translation 0 0 0.05
  children [
    Solid {
      children [
        HingeJoint {
          jointParameters HingeJointParameters {
            axis 0 1 0
            anchor 0 0 0.1
          }
          endPoint Solid {
            translation 0 0 0.55
            rotation 0 1 0 0
            children [
              Gyro {
              }
              InertialUnit {
                name "imu"
              }
              HingeJoint {
                jointParameters HingeJointParameters {
                  axis 0 1 0
                  anchor 0 0 0.55
                }
                device [
                  PositionSensor {
                    name "pendulum position"
                  }
                  RotationalMotor {
                    name "balance motor"
                  }
                ]
                endPoint Solid {
                  translation 0 0 1
                  rotation 0 1 0 0
                  children [
                    Group {
                      children [
                        Solid {
                          translation 0 0 0.6
                          children [
                            Shape {
                              appearance Plastic {
                              }
                              geometry Sphere {
                                radius 0.1
                              }
                            }
                          ]
                          name "Rider Mass"
                          boundingObject Sphere {
                            radius 0.1
                          }
                          physics Physics {
                          }
                        }
                      ]
                    }
                    Shape {
                      appearance Plastic {
                      }
                      geometry Box {
                        size 0.1 0.1 1
                      }
                    }
                  ]
                  name "Rider"
                  boundingObject Shape {
                    geometry Box {
                      size 0.1 0.1 1
                    }
                  }
                  physics Physics {
                  }
                }
              }
              Solid {
                children [
                  Shape {
                    appearance BrushedSteel {
                    }
                    geometry Sphere {
                      radius 0.1
                    }
                  }
                ]
                name "Frame Mass"
                boundingObject Sphere {
                  radius 0.1
                }
                physics Physics {
                }
              }
              Shape {
                appearance BrushedSteel {
                }
                geometry Box {
                  size 0.1 0.1 1
                }
              }
            ]
            name "Frame"
            boundingObject Shape {
              geometry Box {
                size 0.1 0.1 1
              }
            }
            physics Physics {
            }
          }
        }
        Shape {
          appearance Asphalt {
          }
          geometry Box {
            size 2 2 0.1
          }
        }
      ]
      name "Base"
      boundingObject Shape {
        geometry Box {
          size 2 2 0.1
        }
      }
      physics Physics {
      }
    }
  ]
  boundingObject Box {
    size 2 2 0.01
  }
  physics Physics {
  }
}
