#VRML_SIM R2022a utf8
WorldInfo {
  info [
    "Bicycle Simulation"
  ]
  title "Bicycle"
  CFM 0.0003
  ERP 0.6
  basicTimeStep 1
  lineScale 1
  contactProperties [
    ContactProperties {
      coulombFriction [
        8
      ]
      bounce 0.001
      softCFM 0.0003
    }
  ]
}
Viewpoint {
  orientation -0.03355091815675731 -0.021946488731574385 0.9991960205701349 3.6110435432644894
  position 3.1907760174487536 1.4456140707695482 0.8842099908644167
  near 1
  follow "Bicycle"
}
TexturedBackground {
}
TexturedBackgroundLight {
}
CircleArena {
  translation 0 0 -0.0405
  radius 200
  floorTileSize 2 2
  wallThickness 0.1
  wallHeight 1
  wallAppearance OldPlywood {
  }
}
DEF sueprvisor Robot {
  translation 0 0 0.02
  controller ""
  supervisor TRUE
}
DEF MOTORCYCLE Bicycle {
  Rotation 1 0 0 0.01
  CenterMass 22.717
  CenterHeight 0.47
  b 1
  c 0.0526
  FrontWheelR 0.2413
  RearWheelR 0.2413
  Wheelmass 5.689
  FrontforkM 5.105
  tireRadius 0.04
  Addon [
    HingeJoint {
      jointParameters HingeJointParameters {
        position -0.01
        anchor 0.51 0 0.6858
        minStop -1.0472
        maxStop 1.0472
      }
      device [
        PositionSensor {
          name "pendulum_position"
        }
        RotationalMotor {
          name "balance_motor"
          controlPID 0.0001 0 0
          maxTorque 100
        }
      ]
      endPoint Solid {
        translation 0.5099841822839434 0.004999514958683968 1.185701543580023
        rotation -0.999999749897141 -0.0007072468428732429 2.7492704878748722e-06 0.009999963268451413
        name "rider mass"
        boundingObject Sphere {
          radius 0.05
        }
        physics Physics {
          mass 15
        }
      }
    }
  ]
  controller "Venom Model Controller"
}
